---
published: true
title:  "따라하며 배우는 C++ Section 14. 예외 처리"
excerpt: ""

categories:
  - 따배씨++
tags:
  - [C++]

toc: true
toc_sticky: true
 
date: 2022-05-01
last_modified_at: 2022-05-01
---

# 🤔 학습목표
- 따라하며 배우는 C++ Section 14. 예외 처리

# 📃 학습내용
## 📍 **따라하며 배우는 C++ Section 14. 예외 처리**

### **🌱 14.1 예외 처리의 기본**

- Exception Handling

```cpp
#include <iostream>

using namespace std;

int findFirstchar(const char* string, char ch)
{
	for (size_t index = 0; index < strlen(string); ++index)
		if (string[index] == ch)
			return index;

	return -1; // no match
}

int main()
{

}
```

- 찾지못하면 -1을 리턴하는 코드
- char 함수를 호출하는 곳에서 -1이 들어오면 예외처리를 해야하니 불편함

```cpp
#include <iostream>

using namespace std;

double divide(int x, int y, bool& success)
{
	if (y == 0)
	{
		success = false;
		return 0.0;
	}

	success = false;
	return static_cast<double>(x) / y;
}

int main()
{
	bool success;
	double result = divide(5, 3, success);

	if (!success)
		cerr << "An error occurred" << endl;
	else
		cout << "Result is " << result << endl;

}
```

- 분모 y값으로 0값이 들어오면 `divide()` 에서 0.0을 리턴하여 main에서 에러처리

```cpp
#include <iostream>
#include <fstream>

int main()
{
	std::ifstream input_file("temp.txt");
	if (!input_file)
		std::cerr << "Cannot open file" << std::endl;

}
```

- 인풋파일을 초기화 시도하고 문제가 있다면 에러처리

___

함수의 리턴값으로 bool값으로 성공하면 true 실패하면 false로 리턴하는 경우도 있음

___

**위와같은방식 으로 C++ 에서 예외처리 했던 이유**
- 퍼포먼스
- 다른 대체할수있는 문법이 없었기 때문에

**try - throw - catch**

- 위와같은 코드의 예외처리 방법으로 완전 대체할수있는건아님
- 약간 느려짐
  - 퍼포먼스가 굉장히 중요한 부분에서는 try - throw - catch 를 넣지않음
- 빈번하게 사용되는 곳은 예측할수없는일이 많이 발생하는 경우
  - 게임 서버
  - 인터넷 서버
  
- **try**
  - 무언가를 시도하는것
- **throw**
  - 예외를 던진다는 것
- **catch**
  - 던져진 에러를 잡아서 처리한다는것

___

**제곱근 계산 코드**

```cpp
#include <iostream>

using namespace std;

int main()
{
    double x;
    cin >> x;  // 음수 입력시 예외 발생하도록
    
    try
    {
        if (x < 0.0) throw string("Negative input");
        
        cout << std::sqrt(x) << endl;
    }
    catch (string error_message)
    {
        cout << error_message << endl;
    }

    return 0;
}
```

- `try` 문제가 생길 여지가 있는 부분에 집어넣음
  - `cout << std::sqrt(x) << endl;` 문제가없다면 이부분이 실행이됨
- `throw` 문제가 생기면 여기로 던져줌
- `catch` 하는쪽에서 string을 가로챔
- 음수가 입력되면 `try` 에서 `throw` 로 `"Negative input"` 이라는 string 을 catch로 던져서 error_message에 넣음

___

**주의사항**

```cpp
int main()
{
    try
    {
        throw -1.0;
    }
    catch (int x) // Error
    {
        cout << "Catch Integer " << x << endl;
    }
    catch (string error_message)
    {
        cout << error_message << endl;
    }

    return 0;
}
```

- 런타임 에러 발생
  - catch에서 잡아 넣어야하는데 throw 에서 주는타입은 double이고 받는타입은 int형이라 안맞아서 불가능하여 에러발생
- 자동 캐스팅을 안해줌
- 형변환을 엄격하게하기 때문에 throw에서 던지는 타입과 catch에서 받는 타입이 같아야함

### **🌱 14.2 예외처리와 스택 되감기**

- Stack Unwinding

- cout
  - 출력을 버퍼에 담고 endl을 받으면 플러쉬를 바로하고 줄바꿈을 하는 두가지기능을 동시에 수행함
- cerr
  - endl; 없어도 바로 출력함
- clog
- 기능상 차이는 없고 3가지 채널이 있는것

```cpp
#include <iostream>
using namespace std;

void last()
{
	cout << "Last" << endl;  
	cout << "Throws exception" << endl; 

	throw - 1;
	cout << "End Last" << endl;
}

void third()
{
	cout << "Third" << endl; 

	last();

	cout << "End third" << endl;
}

void second()
{
	cout << "Second" << endl;

	try
	{
		third();
	}
	catch (double)
	{
		std::cerr << "Second caught double exception!" << endl;
	}
	cout << "End second" << endl;
};

void first()
{
	cout << "First" << endl;  

	try
	{
		second();
	}
	catch (int)
	{
		std::cerr << "first caught int exception!" << endl;
	}
	cout << "End first" << endl; 
}

int main()
{
	cout << "Start" << endl;  

	try
	{
		first();
	}
	catch (int)
	{
		std::cerr << "main caught int exception!" << endl; 
	}
	cout << "End of main" << endl; 

  // 출력결과
  // Start
  // First
  // Second
  // Third
  // Last
  // Throws exception
  // first caught int exception!
  // End first
  // End of main
}
```

- first() 들어가고 second() 들어감 third() 들어감 last() 들어감 throw - 1 을 만나고 밑에 cout << `"End Last" << endl;` 를 무시하고 first() 의 catch (int) 로 바로 들어옴
- 에러를 못잡았기때문에 `second();` 호출하는 아랫부분 코드는실행이 안됨 catch한 경우에만 실행함

- `first()` 의 `catch (int)` 를 `catch (double)` 로 바꾸면 `main()`의 `catch (int)` 에서 잡음
- `throw` 를 char 타입으로 던지면 런타임에러
  - 처리헤주는것이 없기때문에

___

**예외 처리를 하나하나 다 구현할수 없을때**
- `catch (...)`
  - `...` ellipses 라고함
  - 모든 경우에 대해 다 예외 처리하겠다는 뜻임

```cpp
catch(...)
{
    cerr << "main caught ellipses exception" << endl;
}
```

___

**exception specifier**

```cpp
void last() throw(int)
{
	cout << "Last" << endl;  
	cout << "Throws exception" << endl; 

	throw 'a';

	cout << "End Last" << endl; 
}
```

- `int` 형을 throw 할수도 있다는 뜻
  - 무조건 `int` 형을 throw 한다는것은 아님 
- ms vs 문서 - () 안에 뭘 넣든지 간에 (...) 이라고 가정한다고함
- 예외를 던질가능성이 있는 함수라는 뜻
- `throw()` 와 같이 파라메타가 없으면 예외를 안던질꺼다 라는 뜻이됨

### **🌱 14.3 예외 클래스와 상속**

- 사용자 정의 자료형

```cpp
#include <iostream>

using namespace std;

class MyArray
{
private:
    int m_data[5];
public:
    int& operator [] (const int& index)
    {
        if (index < 0 || index >= 5) throw - 1;
        return m_data[index];
    }
};

void doSomething()
{
    MyArray my_array;

    try
    {
        my_array[100];
    }
    catch (const int& x)
    {
        cerr << "Exception " << x << endl;
    }
}

int main()
{
    doSomething();

    cout << "main" << endl;

    // 출력결과
    // Exception -1
    // main

    return 0;
}
```

___


```cpp
#include <iostream>

class Exception
{
public:
    void report()
    {
        cerr << "Exception report" << endl;
    }
};

class MyArray
{
private:
    int m_data[5];
public:
    int & operator [] (const int & index)
    {
        if (index < 0 || index >= 5) throw Exception();
        return m_data[index];
    }
};

void doSomething()
{
    MyArray my_array;
    
    try
    {
        my_array[100];
    }
    catch (const int & x)
    {
        cerr << "Exception " << x << endl;
    }
    catch (Exception & e)
    {
        e.report();
    }
}

int main()
{
   doSomething();

   cout << "main" << endl;

    return 0;

    // 출력 결과
    // Exception report
    // main  
}
```

___

```cpp
#include <iostream>

using namespace std;

class Exception
{
public:
    void report()
    {
        cerr << "Exception report" << endl;
    }
};

class ArrayException : public Exception
{
public:
    void report()  // 오버라이딩
    {
        cerr << "Array Exception report" << endl;
    }
};

class MyArray
{
private:
    int m_data[5];
public:
    int& operator [] (const int& index)
    {
        if (index < 0 || index >= 5) throw ArrayException();
        return m_data[index];
    }
};

void doSomething()
{
    MyArray my_array;

    try
    {
        my_array[100];
    }
    catch (const int& x)
    {
        cerr << "Exception " << x << endl;
    }
    catch (Exception& e)
    {
        e.report();
    }
}

int main()
{
    doSomething();

    cout << "main" << endl;

    // 출력결과
    // Exception report
    // main

    return 0;
}
```

- throw로 `ArrayException`을 던졌지만 받는쪽에서 `Exception`으로 받기때문에 `Exception`의 `report()` 가 실행이됨
- 상속구조라서 `ArrayException`을 던졌지만 받는쪽에서 `Exception`으로 받을수 있음

___

**주의사항**

```cpp
void doSomething()
{
    MyArray my_array;

    try
    {
        my_array[100];
    }
    catch (const int& x)
    {
        cerr << "Exception " << x << endl;
    }
    catch (Exception& e)
    {
        e.report();
    }
    catch (ArrayException& e)
    {
        e.report();
    }
}
```

- ArrayException의 예외처리를 만들어 줬는데 결과값이 동일함
- 부모클래스가 먼저 캐치를 해버리니까 자식클래스에서 캐치를 못함

```cpp
void doSomething()
{
    MyArray my_array;

    try
    {
        my_array[100];
    }
    catch (const int& x)
    {
        cerr << "Exception " << x << endl;
    }
    catch (ArrayException& e)
    {
        e.report();
    }
    catch (Exception& e)
    {
        e.report();
    }
}
```

- ArrayException를 위로 올려서 순서를 바꿔해결할수 있음

___

```cpp
#include <iostream>

using namespace std;

class Exception
{
public:
    void report()
    {
        cerr << "Exception report" << endl;
    }
};

class ArrayException : public Exception
{
public:
    void report()  // 오버라이딩
    {
        cerr << "Array Exception report" << endl;
    }
};

class MyArray
{
private:
    int m_data[5];
public:
    int& operator [] (const int& index)
    {
        if (index < 0 || index >= 5) throw ArrayException();
        return m_data[index];
    }
};

void doSomething()
{
    MyArray my_array;

    try
    {
        my_array[100];
    }
    catch (const int& x)
    {
        cerr << "Exception " << x << endl;
    }
    catch (ArrayException& e)
    {
        cout << "doSomething()" << endl;
        e.report();
    }
    catch (Exception& e)
    {
        cout << "doSomething()" << endl;
        e.report();
    }
}

int main()
{
    try 
    {
        doSomething();
    }
    catch (ArrayException& e)
    {
        cout << "mian()" << endl;
        e.report();
    }

    //출력결과
    //doSomething()
    //Array Exception report
    
    return 0;
}
```

- `main()` 에서 예외처리를 만들어 줬는데도 `doSomething()` 함수에서 먼저 캐치가 되어 `main()` 의 예외처리는 작동하지않음

**rethrow**

```cpp
#include <iostream>

using namespace std;

class Exception
{
public:
    void report()
    {
        cerr << "Exception report" << endl;
    }
};

class ArrayException : public Exception
{
public:
    void report()  // 오버라이딩
    {
        cerr << "Array Exception report" << endl;
    }
};

class MyArray
{
private:
    int m_data[5];
public:
    int& operator [] (const int& index)
    {
        if (index < 0 || index >= 5) throw ArrayException();
        return m_data[index];
    }
};

void doSomething()
{
    MyArray my_array;

    try
    {
        my_array[100];
    }
    catch (const int& x)
    {
        cerr << "Exception " << x << endl;
    }
    catch (ArrayException& e)
    {
        cout << "doSomething()" << endl;
        e.report();
        throw e; // rethrow
    }
    catch (Exception& e)
    {
        cout << "doSomething()" << endl;
        e.report();
    }
}

int main()
{
    try 
    {
        doSomething();
    }
    catch (ArrayException& e)
    {
        cout << "mian()" << endl;
        e.report();
    }

    //출력결과
    //doSomething()
    //Array Exception report
    //mian()
    //Array Exception report
    
    return 0;
}
```

- 문법은 동일함 `doSomething()`에서 캐치후 `throw e;` 을 해주면 `main()` 의 예외처리가 발동함

___

**rethrow 객체잘림**

```cpp
#include <iostream>

using namespace std;

class Exception
{
public:
    void report()
    {
        cerr << "Exception report" << endl;
    }
};

class ArrayException : public Exception
{
public:
    void report()  // 오버라이딩
    {
        cerr << "Array Exception report" << endl;
    }
};

class MyArray
{
private:
    int m_data[5];
public:
    int& operator [] (const int& index)
    {
        if (index < 0 || index >= 5) throw ArrayException();
        return m_data[index];
    }
};

void doSomething()
{
    MyArray my_array;

    try
    {
        my_array[100];
    }
    catch (const int& x)
    {
        cerr << "Exception " << x << endl;
    }
    //catch (ArrayException& e)
    //{
    //    cout << "doSomething()" << endl;
    //    e.report();
    //    throw e; // rethrow
    //}
    catch (Exception& e)
    {
        cout << "doSomething()" << endl;
        e.report();
        throw e;
    }
}

int main()
{
    try 
    {
        doSomething();
    }
    catch (ArrayException& e)
    {
        cout << "mian()" << endl;
        e.report();
    }
    catch (Exception& e)
    {
        cout << "mian()" << endl;
        e.report();
    }

    //출력결과
    //doSomething()
    //Exception report
    //mian()
    //Exception report

    return 0;
}
```

- `doSomething()` 함수에서 자식클래스로 받아서 rethrow를 해서 객체잘림이되어 `main()`에서 자식클래스로 예외처리가 됨

___

**rethrow 객체잘림없이 보내기**

```cpp
#include <iostream>

using namespace std;

class Exception
{
public:
    void report()
    {
        cerr << "Exception report" << endl;
    }
};

class ArrayException : public Exception
{
public:
    void report()  // 오버라이딩
    {
        cerr << "Array Exception report" << endl;
    }
};

class MyArray
{
private:
    int m_data[5];
public:
    int& operator [] (const int& index)
    {
        if (index < 0 || index >= 5) throw ArrayException();
        return m_data[index];
    }
};

void doSomething()
{
    MyArray my_array;

    try
    {
        my_array[100];
    }
    catch (const int& x)
    {
        cerr << "Exception " << x << endl;
    }
    //catch (ArrayException& e)
    //{
    //    cout << "doSomething()" << endl;
    //    e.report();
    //    throw e; // rethrow
    //}
    catch (Exception& e)
    {
        cout << "doSomething()" << endl;
        e.report();
        throw;
    }
}

int main()
{
    try 
    {
        doSomething();
    }
    catch (ArrayException& e)
    {
        cout << "mian()" << endl;
        e.report();
    }
    catch (Exception& e)
    {
        cout << "mian()" << endl;
        e.report();
    }

    //출력결과
    //doSomething()
    //Exception report
    //mian()
    //Array Exception report

    return 0;
}
```

- 자식 클래스에서 `throw` 를 그대로 적어주면 객체잘림이 발생하지않음
- 받은것 그대로 통튕겨 보낸다는 느낌으로 부모클래스 로 보낸것 그대로 받아서 보낼수 있음

### **🌱 14.4 exception 소개**

- std::exception
- 다양한 경우의 예외에 구현이 되어있음

```cpp
#include <iostream>
#include <string>
#include <exception>

int main()
{
   try
   {
       std::string s;
       s.resize(-1);  // 예외 발생
   }
   catch (std::exception & e)
   {
       std::cout << typeid(e).name() << std::endl;
       std::cerr << e.what() << std::endl;
   }
   
   return 0;
  
  // 출력 결과
  // class std::length_error
  // string too long
}
```

- 오버플로우가 발생되어 `string too long` 이 뜸
- `catch (std::exception & e)` 의 e 가 부모클래스임
- `typeid(e).name()` 로 자식클래스 이름 찾아낼수 있음

**length_error 직접 catch하기**

```cpp
#include <iostream>
#include <string>
#include <exception>

int main()
{
    try
    {
        std::string s;
        s.resize(-1);  // 예외 발생
    }
    catch (std::length_error& e)
    {
        std::cout << "length_error" << std::endl;
        std::cerr << e.what() << std::endl;
    }
    catch (std::exception& e)
    {
        std::cout << typeid(e).name() << std::endl;
        std::cerr << e.what() << std::endl;
    }

    // 출력 결과
    // length_error
    // string too long

    return 0;
}
```

___

```cpp
#include <iostream>
#include <string>
#include <exception>

int main()
{
    try
    {
        throw std::runtime_error("Bad thing happened");
    }

    catch (std::exception& e)
    {
        std::cout << typeid(e).name() << std::endl;
        std::cerr << e.what() << std::endl;
    }

    //출력결과
    //class std::runtime_error
    //Bad thing happened

    return 0;
}
```

- `throw std::runtime_error("Bad thing happened");` 와 같이 std:;exception에 정의되어있는 것을 가져다 쓸수도있음

___

```cpp
#include <iostream>
#include <string>
#include <exception>

class CustomException : public std::exception
{
public:
    const char * what() const noexcept override
    {
        return "Custom exception";
    }
};

int main()
{
   try
   {
       throw CustomException();  // 예외 발생
   }
   catch (std::exception & e)
   {
       std::cout << typeid(e).name() << std::endl;
       std::cerr << e.what() << std::endl;
   }
   
   return 0;

  //  출력 결과
  //  class CustomException
  //  Custom exception
}
```

- 직접만든 CustomException가 std::exception이 다른 자식들처럼 작동되길 원한다면 what() 함수를 오버라이딩 해줘야함
- `noexcept` C++11 이상 컴파일러 사용시 넣어야함
  - 이 함수 안에서는 예외를 던지지 않겠다는 뜻

- what() 함수: 예외 종류에 맞는 에러 원인 메세지를 리턴하는 기능을 하는 함수
  - 에러 메세지를 리턴 함으로 리턴 타입은 `cosnt char *`
- std::exception 클래스의 모든 자식 클래스는 virtual 가상 함수인 what() 함수를 오버라이딩 한다.

### **🌱 14.5 함수 try**

**함수 try 사용 안할때**

```cpp
#include <iostream>
#include <exception>

using namespace std;

void doSomething()
{
    try
    {
        throw - 1;
    }
    catch (...)
    {
        cout << "Catch in doSomething()" << endl;
    }
}
int main()
{
    try
    {
        doSomething();
    }
    catch (...)
    {
        std::cout << "Catch in main()" << std::endl;
    }

    return 0;
}
```

**함수 try**

```cpp
#include <iostream>
#include <exception>

using namespace std;

void doSomething()
try
{
    throw - 1;
}
catch (...)
{
    cout << "Catch in doSomething()" << endl;
}

int main()
{
    try
    {
        doSomething();
    }
    catch (...)
    {
        std::cout << "Catch in main()" << std::endl;
    }

    return 0;
}
```

- 블럭 전체에 대해서 함수 바디에 전체에 대해서 try catch를 붙일수 있음
- 많이 안쓰는 방법임
___

**함수 try x**

```cpp
#include <iostream>
#include <exception>

class A
{
private:
    int m_x;
public:
    A(int x) : m_x(x)
    {
        if (x == 0)
            throw 1;
    }
};

class B : public A
{
public:
    B(int x)
        : A(x)
    {}
};

int main()
{
   try
   {
       B b(0);
   }
   catch (...)
   {
       std::cout << "Catch in main()" << std::endl;
   }
   
   return 0;

  //  출력결과
  //  Catch in main()
}
```

**함수 try**

```cpp
#include <iostream>
#include <exception>

class A
{
private:
    int m_x;
public:
    A(int x) : m_x(x)
    {
        if (x == 0)
            throw 1;
    }
};

class B : public A
{
public:
    B(int x) try : A(x)
    {}

    catch(...)
    {
        std::cout << "Catch in B constructor" << std::endl;
        // throw
    }
};

int main()
{
   try
   {
       B b(0);
   }
   catch (...)
   {
       std::cout << "Catch in main()" << std::endl;
   }
   
   return 0;

  //  실행결과
  //  Catch in B constructor
  //  Catch in main()
}
```

- `B(int x) try : A(x)` 
- `class B` 에서 throw가 없지만 있는것처럼 작동하는것
- 생성자에서 함수 try를 사용했을땐 생성자에서한번잡고 `main()`에서도 잡을수 있음

### **🌱 14.6 예외처리의 위험성과 단점**

**1. 메모리 누수가 발생할수 있음**

```cpp
#include <iostream>
using namespace std;

int main()
{
	try
	{
		int * i = new int[1000000];  // 큰 메모리 할당

		throw "error";

		delete[] i;
	}
	catch (...)
	{
		cout << "Catch" << endl;
	}
	return 0;
}
```

- 정상적인상황에선 delete가 되지만 예외가 발생이되면 throw가 발동되어 catch로 넘어가서 catch에서 i로 접근할수가 없기때문에 메모리 누수가 발생할수 있음

**스마트 포인터**

```cpp
#include <iostream>
#include <memory> // 
using namespace std;

int main()
{
	try
	{
		int * i = new int[1000000];
		unique_ptr<int> up_i(i); // 스마트 포인터

		throw "error";

		// delete[] i; 없어도 됨
	}
	catch (...)
	{
		cout << "Catch" << endl;
	}
	return 0;
}
```

- `up_i` 변수명 아무거나 지어도됨
- 영역을 벗어날때 `unique_ptr` 가 알아서 메모리를 지워줌 throw되서 날라갈때도 알아서 메모리를 처리해줌

**2. 소멸자에서 예외를 던지면 안됨**

```cpp
#include <iostream>
#include <memory>
using namespace std;

class A
{
public:
	~A()
	{
		throw "eroor";  // 금지
	}
};

int main()
{
	try
	{
		A a; 
	}
	catch (...)
	{
		cout << "Catch" << endl;
	}
	return 0;
}
```

- 런타임에러
- 소멸자는 메모리에 있는걸 싹지우고 날려버리는 경우이기 때문에 정상적으로 `"eroor"` 를 던질수 있는상황이 아니라고 보는것
- 소멸자에선 예외를 던질수 없음

___

**3. for문 안쪽에서 빈번하게 try-catch하는 것은 퍼포먼스에 안좋음**

- try-catch 문은  여러 스택을 왔다 갔다 하기도 하기 때문에 연산이 느림
- zero-cost exception

___

**4. 모든 오류를 예외처리로 잡으려고 하지 않기**

- 오류하고 예외는 다름
- 정상적으로 작동하는 것은 if문 등으로 걸러서 받는것이 좋음
  - 사용자 입력등을 다시 입력받도록 하는 것
- 네트워크 서버 돌릴때, 분산처리, 병렬처리 등 하드웨어, 하드디스크에 읽고쓰기할때등 예측할 수 없는 경우에 사용하기
- 논리적으로 예측이 어려운 경우엔 예외를 쓰는 것이 좋음

# 📌참조링크
인프런 **따라하면서 배우는 C++** - [https://www.inflearn.com/course/following-c-plus](https://www.inflearn.com/course/following-c-plus)